Traceback (most recent call last):
  File "D:/Users/xuwenjie/Documents/MyPython/instances/many/ins_10/Loop_Execute_SQL_ELC.py", line 53, in <module>
    sql_tool.cursor.execute(sql)
  File "C:\Pro\Python3\lib\site-packages\pymysql\cursors.py", line 148, in execute
    result = self._query(query)
  File "C:\Pro\Python3\lib\site-packages\pymysql\cursors.py", line 310, in _query
    conn.query(q)
  File "C:\Pro\Python3\lib\site-packages\pymysql\connections.py", line 548, in query
    self._affected_rows = self._read_query_result(unbuffered=unbuffered)
  File "C:\Pro\Python3\lib\site-packages\pymysql\connections.py", line 775, in _read_query_result
    result.read()
  File "C:\Pro\Python3\lib\site-packages\pymysql\connections.py", line 1156, in read
    first_packet = self.connection._read_packet()
  File "C:\Pro\Python3\lib\site-packages\pymysql\connections.py", line 725, in _read_packet
    packet.raise_for_error()
  File "C:\Pro\Python3\lib\site-packages\pymysql\protocol.py", line 221, in raise_for_error
    err.raise_mysql_exception(self._data)
  File "C:\Pro\Python3\lib\site-packages\pymysql\err.py", line 143, in raise_mysql_exception
    raise errorclass(errno, errval)
pymysql.err.OperationalError: (1054, "Unknown column 'so.placeAt' in 'where clause'")
Traceback (most recent call last):
  File "D:/Users/xuwenjie/Documents/MyPython/instances/many/ins_10/Loop_Execute_SQL_ELC.py", line 53, in <module>
    sql_tool.cursor.execute(sql)
  File "C:\Pro\Python3\lib\site-packages\pymysql\cursors.py", line 148, in execute
    result = self._query(query)
  File "C:\Pro\Python3\lib\site-packages\pymysql\cursors.py", line 310, in _query
    conn.query(q)
  File "C:\Pro\Python3\lib\site-packages\pymysql\connections.py", line 548, in query
    self._affected_rows = self._read_query_result(unbuffered=unbuffered)
  File "C:\Pro\Python3\lib\site-packages\pymysql\connections.py", line 775, in _read_query_result
    result.read()
  File "C:\Pro\Python3\lib\site-packages\pymysql\connections.py", line 1156, in read
    first_packet = self.connection._read_packet()
  File "C:\Pro\Python3\lib\site-packages\pymysql\connections.py", line 725, in _read_packet
    packet.raise_for_error()
  File "C:\Pro\Python3\lib\site-packages\pymysql\protocol.py", line 221, in raise_for_error
    err.raise_mysql_exception(self._data)
  File "C:\Pro\Python3\lib\site-packages\pymysql\err.py", line 143, in raise_mysql_exception
    raise errorclass(errno, errval)
pymysql.err.OperationalError: (1054, "Unknown column 'so.placeAt' in 'where clause'")
Traceback (most recent call last):
  File "D:/Users/xuwenjie/Documents/MyPython/instances/many/ins_10/Loop_Execute_SQL_ELC.py", line 53, in <module>
    sql_tool.cursor.execute(sql)
  File "C:\Pro\Python3\lib\site-packages\pymysql\cursors.py", line 148, in execute
    result = self._query(query)
  File "C:\Pro\Python3\lib\site-packages\pymysql\cursors.py", line 310, in _query
    conn.query(q)
  File "C:\Pro\Python3\lib\site-packages\pymysql\connections.py", line 548, in query
    self._affected_rows = self._read_query_result(unbuffered=unbuffered)
  File "C:\Pro\Python3\lib\site-packages\pymysql\connections.py", line 775, in _read_query_result
    result.read()
  File "C:\Pro\Python3\lib\site-packages\pymysql\connections.py", line 1156, in read
    first_packet = self.connection._read_packet()
  File "C:\Pro\Python3\lib\site-packages\pymysql\connections.py", line 725, in _read_packet
    packet.raise_for_error()
  File "C:\Pro\Python3\lib\site-packages\pymysql\protocol.py", line 221, in raise_for_error
    err.raise_mysql_exception(self._data)
  File "C:\Pro\Python3\lib\site-packages\pymysql\err.py", line 143, in raise_mysql_exception
    raise errorclass(errno, errval)
pymysql.err.OperationalError: (1066, "Not unique table/alias: 'p'")
